<?xml version="1.0" encoding="utf-8"?>
<!--
  Joint limits:
    - joint1: -150° to 179°
    - joint2: 0° to 209°
    - joint3: 0 to 179°
    - joint4: ±90°
    - joint5: ±90°
    - joint6: ±120°
  
  Joint motors:
    - joint{1,2,3}: DAMIAO Motor DM4340P, 52.5 rpm, 5.49 rad/s
    - joint{4,5,6}: DAMIAO Motor DM4310, 200 rpm, 20.94 rad/s
    - gripper DAMIAO Motor DM4310, 0.00875m spur gear radius, 0.183225 m/s, 114N
 -->
<robot
  name="YAM_umi">
  <link
    name="base_link">
    <inertial>
      <origin
        xyz="0.0001285 0.0 0.0368758"
        rpy="0 0 0" />
      <mass
        value="0.46369" />
      <inertia
        ixx="0.00024501"
        ixy="0.00000003"
        ixz=" 0.00000148"
        iyy="0.00000003"
        iyz="0.0"
        izz="0.00024245" />
    </inertial>
    <visual>
      <origin
        xyz="0 0 0"
        rpy="0 0 0" />
      <geometry>
        <mesh
          filename="./meshes/YAM/base_link_visual.stl" />
      </geometry>
      <material
        name="">
        <color
          rgba="0.75294 0.75294 0.75294 1" />
      </material>
    </visual>
    <collision>
      <origin
        xyz="0 0 0"
        rpy="0 0 0" />
      <geometry>
        <mesh
          filename="./meshes/YAM/base_link_collision.stl" />
      </geometry>
    </collision>
  </link>
  <link
    name="link1">
    <inertial>
      <origin
        xyz="0.00454425 -0.00000799 0.01512301"
        rpy="0 0 0" />
      <mass
        value="0.0789" />
      <inertia
        ixx="0.00009933"
        ixy="0.0"
        ixz="-0.00000885"
        iyy="0.00003301"
        iyz="0.0"
        izz="0.00009451" />
    </inertial>
    <visual>
      <origin
        xyz="0 0 0"
        rpy="0 0 0" />
      <geometry>
        <mesh
          filename="./meshes/YAM/link1_visual.stl" />
      </geometry>
      <material
        name="">
        <color
          rgba="0.75294 0.75294 0.75294 1" />
      </material>
    </visual>
    <collision>
      <origin
        xyz="0 0 0"
        rpy="0 0 0" />
      <geometry>
        <mesh
          filename="./meshes/YAM/link1_collision.stl" />
      </geometry>
    </collision>
  </link>
  <joint
    name="joint1"
    type="revolute">
    <origin
      xyz="0 0 0.0695"
      rpy="0 0 0" />
    <parent
      link="base_link" />
    <child
      link="link1" />
    <axis
      xyz="0 0 1" />
    <limit
      lower="-3.141592653589793"
      upper="3.141592653589793"
      effort="30"
      velocity="10" />
  </joint>
  <link
    name="link2">
    <inertial>
      <origin
        xyz="-0.12933992 -0.00320508 0.00021895"
        rpy="0 0 0" />
      <mass
        value="1.0796" />
      <inertia
        ixx="0.00056076"
        ixy="-0.00004623"
        ixz="-0.00001654"
        iyy="0.01591761"
        iyz="-0.00000238"
        izz="0.01602363" />
    </inertial>
    <visual>
      <origin
        xyz="0 0 0"
        rpy="0 0 0" />
      <geometry>
        <mesh
          filename="./meshes/YAM/link2_visual.stl" />
      </geometry>
      <material
        name="">
        <color
          rgba="0.75294 0.75294 0.75294 1" />
      </material>
    </visual>
    <collision>
      <origin
        xyz="0 0 0"
        rpy="0 0 0" />
      <geometry>
        <mesh
          filename="./meshes/YAM/link2_collision.stl" />
      </geometry>
    </collision>
  </link>
  <joint
    name="joint2"
    type="revolute">
    <origin
      xyz="0.02 0 0.0385"
      rpy="0 0 0" />
    <parent
      link="link1" />
    <child
      link="link2" />
    <axis
      xyz="0 1 0" />
    <limit
      lower="0"
      upper="3.6651914291880923"
      effort="30"
      velocity="10" />
  </joint>
  <link
    name="link3">
    <inertial>
      <origin
        xyz="0.18044633 -0.00255206 0.05466436"
        rpy="0 0 0" />
      <mass
        value="0.5829" />
      <inertia
        ixx="0.00043953"
        ixy="0.00016484"
        ixz="-0.00053416"
        iyy="0.00459048"
        iyz="0.00002459"
        izz="0.00455211" />
    </inertial>
    <visual>
      <origin
        xyz="0 0 0"
        rpy="0 0 0" />
      <geometry>
        <mesh
          filename="./meshes/YAM/link3_visual.stl" />
      </geometry>
      <material
        name="">
        <color
          rgba="0.75294 0.75294 0.75294 1" />
      </material>
    </visual>
    <collision>
      <origin xyz="0.13 0.0 0.058" rpy="0.0 1.5708 0.0" />
      <geometry>
        <cylinder radius="0.02" length="0.16" />
      </geometry>
    </collision>
  </link>
  <joint
    name="joint3"
    type="revolute">
    <origin
      xyz="-0.264 0 0"
      rpy="0 0 0" />
    <parent
      link="link2" />
    <child
      link="link3" />
    <axis
      xyz="0 -1 0" />
    <limit
      lower="0"
      upper="3.141592653589793"
      effort="30"
      velocity="10" />
  </joint>
  <link
    name="link4">
    <inertial>
      <origin
        xyz="0.05422718 0.0007573 0.05550444"
        rpy="0 0 0" />
      <mass
        value="0.3896" />
      <inertia
        ixx="0.00031996"
        ixy="0.00001339"
        ixz="-0.00013553"
        iyy="0.00039155"
        iyz="0.00001273"
        izz="0.00033280" />
    </inertial>
    <visual>
      <origin
        xyz="0 0 0"
        rpy="0 0 0" />
      <geometry>
        <mesh
          filename="./meshes/YAM/link4_visual.stl" />
      </geometry>
      <material
        name="">
        <color
          rgba="0.75294 0.75294 0.75294 1" />
      </material>
    </visual>
    <collision>
      <origin xyz="0.0620 0.0007 0.0650" rpy="0.0000 0.0000 0.0000" />
      <geometry>
        <cylinder radius="0.0300" length="0.0460" />
      </geometry>
    </collision>
  </link>
  <joint
    name="joint4"
    type="revolute">
    <origin
      xyz="0.244 0 0.06"
      rpy="0 0 0" />
    <parent
      link="link3" />
    <child
      link="link4" />
    <axis
      xyz="0 -1 0" />
    <limit
      lower="-1.5707963267948966"
      upper="1.570796326794896"
      effort="30"
      velocity="10" />
  </joint>
  <link
    name="link5">
    <inertial>
      <origin
        xyz="0.00654054 0.00011122 -0.04050692"
        rpy="0 0 0" />
      <mass
        value="0.3686" />
      <inertia
        ixx="0.00017506"
        ixy="0.00000068"
        ixz="0.00000629"
        iyy="0.00018162"
        iyz="0.00000014"
        izz="0.00014814" />
    </inertial>
    <visual>
      <origin
        xyz="0 0 0"
        rpy="0 0 0" />
      <geometry>
        <mesh
          filename="./meshes/YAM/link5_visual.stl" />
      </geometry>
      <material
        name="">
        <color
          rgba="0.75294 0.75294 0.75294 1" />
      </material>
    </visual>
    <collision>
      <origin xyz="0.0052 0.0000 -0.0410" rpy="0.0000 1.5708 0.0000" />
      <geometry>
        <cylinder radius="0.0300" length="0.0450" />
      </geometry>
    </collision>
  </link>
  <joint
    name="joint5"
    type="revolute">
    <origin
      xyz="0.062 0 0.0425"
      rpy="0 0 0" />
    <parent
      link="link4" />
    <child
      link="link5" />
    <axis
      xyz="0 0 -1" />
    <limit
      lower="-1.5707963267948966"
      upper="1.5707963267948966"
      effort="30"
      velocity="10" />
  </joint>
  <link
    name="link6">
    <inertial>
      <origin
        xyz="0.05171042 -0.0047113 0.02070167"
        rpy="0 0 0" />
      <mass
        value="0.8834" />
      <inertia
        ixx="0.00165990"
        ixy="-0.00013386"
        ixz="0.00056002"
        iyy="0.00259619"
        iyz="0.00023307"
        izz="0.00197985" />
    </inertial>
    <visual>
      <origin
        xyz="0 0 0"
        rpy="0 0 0" />
      <geometry>
        <mesh
          filename="./meshes/YAM/link6_visual.stl" />
      </geometry>
      <material
        name="">
        <color
          rgba="0.75294 0.75294 0.75294 1" />
      </material>
    </visual>
    <collision>
      <origin
        xyz="0 0 0"
        rpy="0 0 0" />
      <geometry>
        <mesh
          filename="./meshes/YAM/link6_collision.stl" />
      </geometry>
    </collision>
  </link>
  <joint
    name="joint6"
    type="revolute">
    <origin
      xyz="0.032 0 -0.0425"
      rpy="0 0 0" />
    <parent
      link="link5" />
    <child
      link="link6" />
    <axis
      xyz="1 0 0" />
    <limit
      lower="-1.5707963267948966"
      upper="1.5707963267948966"
      effort="30"
      velocity="10" />
  </joint>

  <link name="eef_link">
    <inertial>
      <mass value="0.0" />
      <origin xyz="0.0 0.0 0.0" rpy="0 0 0" />
      <inertia ixx="0.0" ixy="0.0" ixz="0.0" iyy="0.0" iyz="0.0" izz="0.0" />
    </inertial>
  </link>

  <joint name="gripper_fixed_joint" type="fixed">
    <origin xyz="0.22 0.0 0.0" rpy="0 0 0" />
    <parent link="link6" />
    <child link="eef_link" />
  </joint>
</robot>